const AppError = require('../utils/appError');
const catchAsync = require('../utils/catchAsync');

// THIS works because the js closures which is a fancy way of saying that the inner function has access to the outer function's variables after the outer function has returned.
exports.deleteOne = (Model) =>
  catchAsync(async (req, res, next) => {
    const doc = await Model.findByIdAndDelete(req.params.id);

    if (!doc) {
      return next(new AppError('No document found with this ID'));
    }

    res.status(204).json({
      status: 'success',
      data: null,
    });
  });

exports.updateOne = (Model) =>
  catchAsync(async (req, res, next) => {
    const doc = await Model.findByIdAndUpdate(req.params.id, req.body, {
      new: true,
      runValidators: true,
    });

    if (!doc) {
      return next(new AppError('No document found with this ID'));
    }
    res.status(200).json({
      status: 'success',
      data: {
        data: doc,
      },
    });
  });

exports.createOne = (Model) =>
  catchAsync(async (req, res, next) => {
    const doc = await Model.create(req.body);

    res.status(201).json({
      status: 'success',
      data: {
        data: doc,
      },
    });
  });
